<?xml version="1.0"?>
<robot name="scara">

  <material name="blue">
    <color rgba="0.3 0.54 0.75 1"/>
  </material>

  <material name="white">
    <color rgba="1 1 1 1"/>
  </material>

  <material name="gray">
    <color rgba="0.5 0.5 0.5 1"/>
  </material>

  <material name="black">
    <color rgba="0 0 0 1"/>
  </material>
  
  <link name="world"/>

  <joint name="joint_fix" type="fixed">
    <parent link="world"/>
    <child link="base_link"/>
  </joint>

  <link name="base_link">
    <visual>
      <origin xyz="0 0 0.2" rpy="0 0 0"/>
      <geometry>
	<cylinder length="0.4" radius="0.1"/>
      </geometry>
      <material name="gray"/>
    </visual>
    <inertial>
      <origin xyz="0 0 0.2" rpy="0 0 0"/>
      <mass value="1"/>
      <inertia
	  ixx="1.0" ixy="0.0" ixz="0.0"
	  iyy="1.0" iyz="0.0"
	  izz="1.0"/>
    </inertial>
  </link>

  <joint name="joint1" type="revolute">
    <parent link="base_link"/>
    <child link="arm1"/>
    <origin xyz="0 0 0.4" rpy="0 0 0"/>
    <axis xyz="0 0 1"/>
    <limit effort="10" velocity="10" lower="-3.1416" upper="3.1416"/>
  </joint>

  <link name="arm1">
    <visual>
      <origin xyz="0 0.25 0.05" rpy="0 0 0"/>
      <geometry>
	<box size="0.1 0.6 0.1"/>
      </geometry>
      <material name="gray"/>
    </visual>
    <inertial>
      <origin xyz="0 0.25 0.05" rpy="0 0 0"/>
      <mass value="1"/>
      <inertia
	  ixx="0.001" ixy="0.0" ixz="0.0"
	  iyy="0.001" iyz="0.0"
	  izz="0.001"/>
    </inertial>
  </link>

  <joint name="joint2" type="revolute">
    <parent link="arm1"/>
    <child link="arm2"/>
    <origin xyz="0 0.5 0" rpy="0 0 0"/>
    <axis xyz="0 0 1"/>
    <limit effort="10" velocity="10" lower="-2.6" upper="2.6"/>
  </joint>
  
  <link name="arm2">
    <visual>
      <origin xyz="0 0.1 -0.05" rpy="0 0 0"/>
      <geometry>
	<box size="0.1 0.3 0.1"/>
      </geometry>
      <material name="blue"/>
    </visual>
    <inertial>
      <origin xyz="0 0.2 -0.05" rpy="0 0 0"/>
      <mass value="1"/>
      <inertia
	  ixx="0.001" ixy="0.0" ixz="0.0"
	  iyy="0.001" iyz="0.0"
	  izz="0.001"/>
    </inertial>
  </link>

  <joint name="joint3" type="prismatic">
    <parent link="arm2"/>
    <child link="gripper"/>
    <origin xyz="0 0.2 0" rpy="0 0 0"/>
    <axis xyz="0 0 -1"/>
    <limit effort="20" velocity="20" lower="0.0" upper="0.2"/>
  </joint>

  <link name="gripper">
    <visual>
      <origin xyz="0 0 -0.02" rpy="0 0 0"/>
      <geometry>
	<cylinder length="0.24" radius="0.04"/>
      </geometry>
      <material name="gray"/>
    </visual>
    <inertial>
      <origin xyz="0 0 -0.02" rpy="0 0 0"/>
      <mass value="0.01"/>
      <inertia
	  ixx="0.001" ixy="0.0" ixz="0.0"
	  iyy="0.001" iyz="0.0"
	  izz="0.001"/>
    </inertial>
  </link>

  <link name="gripper_base">
    <visual>
      <origin xyz="0 0 0" rpy="0 0 0"/>
      <geometry>
	<box size="0.08 0.01 0.01"/>
      </geometry>
      <material name="gray"/>
    </visual>
    <inertial>
      <origin xyz="0 0 0" rpy="0 0 0"/>
      <mass value="0.01"/>
      <inertia
	  ixx="0.001" ixy="0.0" ixz="0.0"
	  iyy="0.001" iyz="0.0"
	  izz="0.001"/>
    </inertial>
  </link>

  <joint name="gripper_rot" type="revolute">
    <origin xyz="0 0 -0.135" rpy="0 0 0"/>
    <parent link="gripper"/>
    <child link="gripper_base"/>
    <axis xyz="0 0 1"/>
    <limit effort="10" velocity="10" lower="-1.5708" upper="1.5708"/>
  </joint>

  <!-- left finger -->
  <link name="gripper_left_finger_up">
    <visual>
      <origin xyz="0 0 -0.02" rpy="0 0 0"/>
      <geometry>
	<box size="0.01 0.01 0.05"/>
      </geometry>
      <material name="white"/>
    </visual>
    <inertial>
      <origin xyz="0 0 -0.02" rpy="0 0 0"/>
      <mass value="0.001"/>
      <inertia
	  ixx="0.001" ixy="0.0" ixz="0.0"
	  iyy="0.001" iyz="0.0"
	  izz="0.001"/>
    </inertial>
  </link>
  <link name="gripper_left_finger_down">
    <visual>
      <origin xyz="0 0 -0.01" rpy="0 0 0"/>
      <geometry>
	<box size="0.01 0.01 0.02"/>
      </geometry>
      <material name="black"/>
    </visual>
    <inertial>
      <origin xyz="0 0 -0.01" rpy="0 0 0"/>
      <mass value="0.001"/>
      <inertia
	  ixx="0.001" ixy="0.0" ixz="0.0"
	  iyy="0.001" iyz="0.0"
	  izz="0.001"/>
    </inertial>
  </link>
  <joint name="gripper_left_join" type="fixed">
    <origin xyz="0 0 -0.04" rpy="0 -0.2 0"/>
    <parent link="gripper_left_finger_up"/>
    <child link="gripper_left_finger_down"/>
  </joint>

  <joint name="gripper_left" type="prismatic">
    <origin xyz="-0.04 0 0" rpy="0 0 0"/>
    <parent link="gripper_base"/>
    <child link="gripper_left_finger_up"/>
    <axis xyz="1 0 0"/>
    <limit effort="20" velocity="20" lower="0.0" upper="0.03"/>
  </joint>

  <!-- right finger -->
  <link name="gripper_right_finger_up">
    <visual>
      <origin xyz="0 0 -0.02" rpy="0 0 0"/>
      <geometry>
	<box size="0.01 0.01 0.05"/>
      </geometry>
      <material name="white"/>
    </visual>
    <inertial>
      <origin xyz="0 0 -0.02" rpy="0 0 0"/>
      <mass value="0.001"/>
      <inertia
	  ixx="0.001" ixy="0.0" ixz="0.0"
	  iyy="0.001" iyz="0.0"
	  izz="0.001"/>
    </inertial>
  </link>
  <link name="gripper_right_finger_down">
    <visual>
      <origin xyz="0 0 -0.01" rpy="0 0 0"/>
      <geometry>
	<box size="0.01 0.01 0.02"/>
      </geometry>
      <material name="black"/>
    </visual>
    <inertial>
      <origin xyz="0 0 -0.01" rpy="0 0 0"/>
      <mass value="0.001"/>
      <inertia
	  ixx="0.001" ixy="0.0" ixz="0.0"
	  iyy="0.001" iyz="0.0"
	  izz="0.001"/>
    </inertial>
  </link>
  <joint name="gripper_right_join" type="fixed">
    <origin xyz="0 0 -0.04" rpy="0 0.2 0"/>
    <parent link="gripper_right_finger_up"/>
    <child link="gripper_right_finger_down"/>
  </joint>

  <joint name="gripper_right" type="prismatic">
    <origin xyz="0.04 0 0" rpy="0 0 0"/>
    <parent link="gripper_base"/>
    <child link="gripper_right_finger_up"/>
    <axis xyz="-1 0 0"/>
    <limit effort="20" velocity="20" lower="0.0" upper="0.03"/>
  </joint>
</robot>
